Workbook

Sheet Cómo usar · How to
A1: BIBLIOTECA DE SERMONES — WATV Media Cast (Español + English)
A3: QUÉ ES ESTO · WHAT THIS IS
A4: Sermones, sermones resumidos y la serie mensual «Palabras de este mes» (Monthly Sermon Series),
A5: en español e inglés. Se leyeron los subtítulos hablados de cada vídeo, así que se puede buscar por TEMA,
A6: no solo por el título: ira y enojo, paciencia, perdón, diezmo y ofrenda, hijos, pruebas, humildad…
A7: COBERTURA · COVERAGE: índice por temas en 1861 de 1875 vídeos (4,611,304 palabras de transcripción leídas). Incluye 55 vídeos de la serie mensual.
A8: Videos without a topic index still appear in the Catalog with the site's own tags and summary.
A10: Every sermon, summary sermon and the monthly sermon series, in Spanish and English. The spoken subtitles
A11: of each video were read, so you can search by SUBJECT, not just by title.
A13: HOJAS · SHEETS
A14: Catálogo / Catalog — todos los vídeos, uno por fila, con «Idioma» (ES/EN) y filtros en la fila 1.
A15: Temas / Topics — cada tema con los vídeos que lo tratan, ordenados por cuánto lo tratan.
... A30: • Fuente / Source: watvmedia.org — sitio oficial. Los enlaces abren el vídeo original.

Sheet Buscar · Search
A1: Palabra o tema a buscar / Keyword or subject: | B1: enojo
A3: Vídeos que coinciden / matching videos: | B3: =COUNTIF('Catálogo · Catalog'!A:A,"SÍ")
A5: 1. Escribe tu palabra en la celda amarilla (B1). / Type your keyword in the yellow cell (B1).
A6: 2. Ve a «Catálogo» y filtra la columna «✅» = SÍ. / Go to «Catálogo» and filter «✅» = SÍ.
A7: 3.
A8: Busca sin acentos: «perdon», «ira», «diezmo», «hijos» / «anger», «tithe», «patience».
A9: Si la columna ✅ aparece vacía, pulsa F9 / If ✅ is blank, press F9.

Sheet Catálogo · Catalog
A1: ✅ | B1: Nº | C1: Idioma | D1: Tipo | E1: Título / Title | F1: Sección / Section | G1: Categoría / Category | H1: Canal / Channel | I1: Temas detectados / Topics | J1: Etiquetas / Tags | K1: Palabras frecuentes | L1: Duración | M1: Fecha | N1: Vistas | O1: Resumen / Summary | P1: Enlace / Link | Q1: YouTube
A2: =IF('Buscar · Search'!$B$1="","",IF(ISNUMBER(SEARCH('Buscar · Search'!$B$1,$E2&" "&$F2&" "&$G2&" "&$H2&" "&$I2&" "&$J2&" "&$K2&" "&$O2)),"SÍ","")) | B2: 1 | C2: ES | D2: Mensual | E2: Deben nacer de nuevo para entrar en el Reino de los Cielos | G2: Palabras de este mes | H2: Mother | I2: Amor y amor fraternal (20); Cielo, infierno y alma (9); Educación de los hijos y familia (8); Salvación y vida eterna (4); Evangelización y predicación (3); Avaricia y materialismo (3); Arrepentimiento (3) | K2: amor, cielo | L2: 05:24 | M2: 14 dic 2023 | N2: 14.331 | O2: Así como los hijos se parecen a sus padres,los hijos de Dios deben convertirse enamor pues Dios es amor.Él murió en lugar de Sus hijos queestaban destinados a entrar en elinfierno eterno debido a su p... | P2: https://watvmedia.org/es/media/be-born-again | Q2: https://youtu.be/5RniY9vQTW8
A3: =IF('Buscar · Search'!$B$1="","",IF(ISNUMBER(SEARCH('Buscar · Search'!$B$1,$E3&" "&$F3&" "&$G3&" "&$H3&" "&$I3&" "&$J3&" "&$K3&" "&$O3)),"SÍ","")) | B3: 2 | C3: ES | D3: Mensual | E3: Nuestra patria es el cielo: somos extranjeros sobre la tierra | G3: Palabras de este mes | H3: Mother | I3: Cielo, infierno y alma (10); Salvación y vida eterna (7); Educación de los hijos y familia (7); Arrepentimiento (6); Padre celestial (Cristo Ahnsahnghong) (5); Avaricia y materialismo (5); Familia celestial y Sion (3); Enfermedad y sanidad (3) | K3: cielo, reino, tierra, cielos, musica, mundo, patria | L3: 06:49 | M3: 5 mar 2025 | N3: 8.808 | O3: La razón por la que sufrimos el calor y el frío y padecemos mucho dolor, pena y amargura es porque somos extranjeros en esta tierra; este no es nuestro hogar.Dios se apiadó de la humanidad. Para lleva... | P3: https://watvmedia.org/es/media/our-home-is-heaven-we-are-strangers-in-this-world | Q3: https://youtu.be/xB3G2tj59lo
A4: =IF('Buscar · Search'!$B$1="","",IF(ISNUMBER(SEARCH('Buscar · Search'!$B$1,$E4&" "&$F4&" "&$G4&" "&$H4&" "&$I4&" "&$J4&" "&$K4&" "&$O4)),"SÍ","")) | B4: 3 | C4: ES | D4: Mensual | E4: El lino fino de Dios | G4: Palabras de este mes | H4: Mother | I4: Amor y amor fraternal (14); Salvación y vida eterna (13); Avaricia y materialismo (6); Palabras y lengua (hablar bien) (5); Pascua (4); La Biblia y su autoridad (3); Ira y enojo (control del temperamento) (3); Educación de los hijos y familia (3) | K4: amor, musica, reino, cielos, mundo | L4: 08:02 | M4: 30 abr 2025 | N4: 8.032 | O4: La Biblia, la palabra de Dios, es un libro que educa a la humanidad y muestra el camino de la salvación. Dios dice que, si llegamos a ser uno en amor, habremos cumplido la ley y nos explica que cuando... | P4: https://watvmedia.org/es/media/gods-linen | Q4: https://youtu.be/oZIkjRfwzJ0
A5: =IF('Buscar · Search'!$B$1="","",IF(ISNUMBER(SEARCH('Buscar · Search'!$B$1,$E5&" "&$F5&" "&$G5&" "&$H5&" "&$I5&" "&$J5&" "&$K5&" "&$O5)),"SÍ","")) | B5: 4 | C5: ES | D5: Mensual | E5: Una fe que practica la unidad | G5: Palabras de este mes | H5: Mother | I5: Cielo, infierno y alma (10); Unidad y armonía (6); Salvación y vida eterna (4); Perdón y reconciliación (4); Pruebas y tribulación (3); Evangelización y predicación (3); Enfermedad y sanidad (3) | K5: cielo, naturaleza | L5: 07:10 | M5: 18 oct 2024 | N5: 6.934 | O5: Ya que los seres humanos vinimos a esta tierra cometiendo graves pecados en el cielo, nuestros pecados no se limpian sin dolor. Además, siguen muchos dolores y sufrimientos en el proceso de nacer de n... | P5: https://watvmedia.org/es/media/united-faith | Q5: https://youtu.be/apILzd6Tk4w
A6: =IF('Buscar · Search'!$B$1="","",IF(ISNUMBER(SEARCH('Buscar · Search'!$B$1,$E6&" "&$F6&" "&$G6&" "&$H6&" "&$I6&" "&$J6&" "&$K6&" "&$O6)),"SÍ","")) | B6: 5 | C6: ES | D6: Mensual | E6: Edifiquemos a los demás con palabras amables y hermosas | G6: Palabras de este mes | H6: Mother | I6: Palabras y lengua (hablar bien) (22); Salvación y vida eterna (7); Educación de los hijos y familia (5); Ira y enojo (control del temperamento) (4); Fe y confianza en Dios (4); Alegría y felicidad (4); Humildad y orgullo (3) | K6: musica, sola | L6: 07:34 | M6: 17 jun 2025 | N6: 6.223 | O6: Las palabras son muy importantes en nuestra familia, en el mundo y en nuestra vida de la fe. En el libro de Génesis, Satanás condujo a Adán y Eva a la muerte con solo una palabra, y el ladrón que fue ... | P6: https://watvmedia.org/es/media/let-us-bestow-grace-with-good-and-beautiful-words | Q6: https://youtu.be/fkZ6-vsKyWk
A7: =IF('Buscar · Search'!$B$1="","",IF(ISNUMBER(SEARCH('Buscar · Search'!$B$1,$E7&" "&$F7&" "&$G7&" "&$H7&" "&$I7&" "&$J7&" "&$K7&" "&$O7)),"SÍ","")) | B7: 6 | C7: ES | D7: Mensual | E7: ¿Haciendo qué cosa heredaré la vida eterna? | G7: Palabras de este mes | H7: Mother | I7: Amor y amor fraternal (40); Cielo, infierno y alma (13); Salvación y vida eterna (8); Padre celestial (Cristo Ahnsahnghong) (6); Evangelización y predicación (5); Pascua (4); Palabras y lengua (hablar bien) (4) | K7: amor, misericordia, eterna, cielo, musica | L7: 06:53 | M7: 22 oct 2024 | N7: 6.007 | O7: Cuando alguien preguntó: “¿Haciendo qué cosa heredaré la vida eterna?”,Jesús le respondió utilizando la parábola del buen samaritano.Él enseñó que es importante guardar los mandamientos de Dios,pero a... | P7: https://watvmedia.org/es/media/how-eternal-life | Q7: https://youtu.be/CCXnn3rH3Ac
A8: =IF('Buscar · Search'!$B$1="","",IF(ISNUMBER(SEARCH('Buscar · Search'!$B$1,$E8&" "&$F8&" "&$G8&" "&$H8&" "&$I8&" "&$J8&" "&$K8&" "&$O8)),"SÍ","")) | B8: 7 | C8: ES | D8: Mensual | E8: Las cosas buenas y las cosas malas | G8: Palabras de este mes | H8: Mother | I8: Cielo, infierno y alma (11); Educación de los hijos y familia (8); Perdón y reconciliación (6); Palabras y lengua (hablar bien) (6); Amor y amor fraternal (6); Arrepentimiento (4); Salvación y vida eterna (3) | K8: buenas, cielo, musica | L8: 06:04 | M8: 24 ene 2025 | N8: 5.723 | O8: Al igual que en la parábola de pescar y separar los buenos peces de los malos, el reino de los cielos no es un lugar al que todos puedan acceder. Solo aquellos con una naturaleza amable, que considera... | P8: https://watvmedia.org/es/media/the-good-and-the-bad | Q8: https://youtu.be/F9SlsNoX-E0
A9: =IF('Buscar · Search'!$B$1="","",IF(ISNUMBER(SEARCH('Buscar · Search'!$B$1,$E9&" "&$F9&" "&$G9&" "&$H9&" "&$I9&" "&$J9&" "&$K9&" "&$O9)),"SÍ","")) | B9: 8 | C9: ES | D9: Mensual | E9: Conformarse a las sanas palabras y a la doctrina que es conforme a la piedad | G9: Palabras de este mes | H9: Mother | I9: Educación de los hijos y familia (8); Cielo, infierno y alma (5); Salvación y vida eterna (4); La Biblia y su autoridad (4); Palabras y lengua (hablar bien) (3); Amor y amor fraternal (3) | K9: piedad, musica, cielo, doctrina, conforme, reino | L9: 07:05 | M9: 22 nov 2024 | N9: 5.455 | O9: Ya que el pueblo del reino de los cielos son los hijos e hijas del Poderoso Creador Dios Ahnsahnghong, siempre debemos llevar una vida piadosa como hijos de Dios y dedicarnos a la palabra de Dios. “Co... | P9: https://watvmedia.org/es/media/focus-on-reverence-and-the-word | Q9: https://youtu.be/x9s09WQ8vgU
A10: =IF('Buscar · Search'!$B$1="","",IF(ISNUMBER(SEARCH('Buscar · Search'!$B$1,$E10&" "&$F10&" "&$G10&" "&$H10&" "&$I10&" "&$J10&" "&$K10&" "&$O10)),"SÍ","")) | B10: 9 | C10: ES | D10: Mensual | E10: Todas las naciones correrán a Sion por el camino de la vida | G10: Palabras de este mes | H10: Mother | I10: Salvación y vida eterna (16); Familia celestial y Sion (12); Pascua (11); Fiestas solemnes de Dios (5); La Biblia y su autoridad (4); Evangelización y predicación (4); El nuevo pacto (4) | K10: sion, pascua, eterna, salvacion, musica, fiesta, vino | L10: 06:58 | M10: 5 dic 2024 | N10: 5.328 | O10: La razón por la que Dios trae desastres en esta época es porque las personas abandonan su palabra.Jesús en su primera venida y Cristo Ahnsahnhong, Jesús que vino por segunda vez, trajeron la Pascua de... | P10: https://watvmedia.org/es/media/all-nations-find-their-way-to-zion | Q10: https://youtu.be/9tuU9dat83A
A11: =IF('Buscar · Search'!$B$1="","",IF(ISNUMBER(SEARCH('Buscar · Search'!$B$1,$E11&" "&$F11&" "&$G11&" "&$H11&" "&$I11&" "&$J11&" "&$K11&" "&$O11)),"SÍ","")) | B11: 10 | C11: ES | D11: Mensual | E11: Según las palabras de la profecía | G11: Palabras de este mes | H11: Mother | I11: Salvación y vida eterna (11); Cristo Ahnsahnghong y las profecías (9); La Biblia y su autoridad (8); Palabras y lengua (hablar bien) (7); Pascua (6); Cielo, infierno y alma (6); Arrepentimiento (4); Familia celestial y Sion (3) | K11: biblia, pascua, salvacion, camino, cielo, musica | L11: 06:23 | M11: 22 nov 2024 | N11: 5.270 | O11: Dios ha predestinado lo que sucederá incluso antes de la creación y ha estado llevando a cabo la obra de la redención según las profecías de la Biblia. Por lo tanto, debemos creer en las profecías.La ... | P11: https://watvmedia.org/es/media/words-of-prophecy | Q11: https://youtu.be/vZA_QFXcm0k
A12: =IF('Buscar · Search'!$B$1="","",IF(ISNUMBER(SEARCH('Buscar · Search'!$B$1,$E12&" "&$F12&" "&$G12&" "&$H12&" "&$I12&" "&$J12&" "&$K12&" "&$O12)),"SÍ","")) | B12: 11 | C12: ES | D12: Mensual | E12: Mirad, velad y orad | G12: Palabras de este mes | H12: Mother | I12: Salvación y vida eterna (10); Padre celestial (Cristo Ahnsahnghong) (4); Educación de los hijos y familia (4); Pascua (3); Cristo Ahnsahnghong y las profecías (3) | K12: nombre, salvos | L12: 05:51 | M12: 24 ene 2025 | N12: 5.128 | O12: La Iglesia de Dios, donde se celebra la verdad de la Pascua que nos protege del desastre, es Sion.Dios ha proporcionado refugio en cada época: el arca a Noé, Zoar a Lot, y Pella durante la destrucción... | P12: https://watvmedia.org/es/media/be-careful-stay-awake | Q12: https://youtu.be/mN68TO7sOws
A13: =IF('Buscar · Search'!$B$1="","",IF(ISNUMBER(SEARCH('Buscar · Search'!$B$1,$E13&" "&$F13&" "&$G13&" "&$H13&" "&$I13&" "&$J13&" "&$K13&" "&$O13)),"SÍ","")) | B13: 12 | C13: ES | D13: Mensual | E13: La mentalidad de un hijo y la mentalidad de un siervo | G13: Palabras de este mes | H13: Mother | I13: Educación de los hijos y familia (11); Salvación y vida eterna (7); Padre celestial (Cristo Ahnsahnghong) (7); Evangelización y predicación (5); Amor y amor fraternal (5); Cielo, infierno y alma (4); Enfermedad y sanidad (3) | K13: musica, celestial, reino, amor | L13: 06:50 | M13: 10 feb 2025 | N13: 4.857 | O13: Si somos hijos de Abraham, nuestra fe debe ser tan firme como la de Abraham,y si somos hijos de Dios, debemos salvar a las almas afligidas con amor, tal como Dios lo hizo.El sacerdocio real celestial ... | P13: https://watvmedia.org/es/media/the-spirit-of-a-son-and-the-spirit-of-a-servant | Q13: https://youtu.be/X_RsRokRoiI
... A28: =IF('Buscar · Search'!$B$1="","",IF(ISNUMBER(SEARCH('Buscar · Search'!$B$1,$E28&" "&$F28&" "&$G28&" "&$H28&" "&$I28&" "&$J28&" "&$K28&" "&$O28)),"SÍ","")) | B28: 27 | C28: ES | D28: Mensual | E28: La felicidad de los ciudadanos celestiales | G28: Palabras de este mes | H28: Mother | I28: Educación de los hijos y familia (10); Amor y amor fraternal (7); Salvación y vida eterna (6); Alegría y felicidad (6); Cielo, infierno y alma (5); Padre celestial (Cristo Ahnsahnghong) (4); Evangelización y predicación (4); Espíritu Santo y la Esposa (4) | K28: musica, reino, cielos, amor | L28: 07:15 | M28: 17 sept 2026 | N28: 361 | O28: Las personas que viven en esta tierra llevan una vida fatigosa, tengan mucho o poco. Al guardar la Pascua del nuevo pacto, nos hemos convertido en un cuerpo y una familia con Dios. Ya que Dios se ha c... | P28: https://watvmedia.org/es/media/heavenly-citizens-happiness | Q28: https://youtu.be/5rBt_xoVDxU
A29: =IF('Buscar · Search'!$B$1="","",IF(ISNUMBER(SEARCH('Buscar · Search'!$B$1,$E29&" "&$F29&" "&$G29&" "&$H29&" "&$I29&" "&$J29&" "&$K29&" "&$O29)),"SÍ","")) | B29: 28 | C29: ES | D29: Sermón | E29: Moisés, Jesús y la cruz | F29: Sermón | G29: Verdad | I29: La Biblia y su autoridad (63); Salvación y vida eterna (26); Cristo Ahnsahnghong y las profecías (20); Palabras y lengua (hablar bien) (11); Educación de los hijos y familia (11); Cielo, infierno y alma (10); Fe y confianza en Dios (9); Avaricia y materialismo (8) | J29: La cruz | K29: cruz, moises, serpiente, jesus, bronce, esto, jehova, israelitas, manos, biblia, discipulos, cuerda | L29: 43:04 | M29: 3 mar 2020 | N29: 260.398 | O29: Dios nos mostró la verdadera identidad de la cruz a través de MoisésMoisés fue una figura profética de la realidad de Jesús. Los israelitas ganaron la batalla de Refidimporque Moisés levantó sus manos... | P29: https://watvmedia.org/es/media/moses-jesus-and-the-cross | Q29: https://youtu.be/cxwcPg8IMw0
A30: =IF('Buscar · Search'!$B$1="","",IF(ISNUMBER(SEARCH('Buscar · Search'!$B$1,$E30&" "&$F30&" "&$G30&" "&$H30&" "&$I30&" "&$J30&" "&$K30&" "&$O30)),"SÍ","")) | B30: 29 | C30: ES | D30: Sermón | E30: Superemos la tentación y obtengamos el reino de los cielos | F30: Sermón | G30: Fe, Carácter | I30: La Biblia y su autoridad (40); Fe y confianza en Dios (40); Pruebas y tribulación (34); Educación de los hijos y familia (28); Cielo, infierno y alma (24); Avaricia y materialismo (16); Salvación y vida eterna (10); Dinero, trabajo y provisión (10) | J30: Fe, Resistencia | K30: satanas, tentacion, jehova, jesus, tierra, esto, cada, mundo, tentaciones, prueba, cielo, pruebas | L30: 44:00 | M30: 17 abr 2020 | N30: 245.181 | O30: Ya que Dios concede a sus hijos las bendiciones del cieloa través de cada culto, el acto de creer en Diosy adorarlo es en sí mismo alegría y felicidad.Los miembros de la Iglesia de Dios que vencen tod... | P30: https://watvmedia.org/es/media/lets-overcome-temptation-and-gain-the-kingdom-of-heaven | Q30: https://youtu.be/tnGd9GBR4t0
A31: =IF('Buscar · Search'!$B$1="","",IF(ISNUMBER(SEARCH('Buscar · Search'!$B$1,$E31&" "&$F31&" "&$G31&" "&$H31&" "&$I31&" "&$J31&" "&$K31&" "&$O31)),"SÍ","")) | B31: 30 | C31: ES | D31: Sermón | E31: La Madre Jerusalén | F31: Sermón | G31: Padre/Madre | I31: La Biblia y su autoridad (60); Educación de los hijos y familia (43); Amor y palabra de Dios Madre (31); Padre celestial (Cristo Ahnsahnghong) (29); Espíritu Santo y la Esposa (21); Palabras y lengua (hablar bien) (15); Salvación y vida eterna (10); La creación y el diseño de Dios (9) | J31: Madre, Dios Elohim | K31: esposa, creo, futuro, biblia, esto, voluntad, veamos, jesus, conocer, escrito, imagen, tierra | L31: 33:40 | M31: 13 abr 2018 | N31: 200.651 | O31: Todas las cosas de este mundo fueron creadas por la voluntad de Dios.Dios creó a todos los seres vivos para que recibieran vidaa través de sus madres. Esta es la gran voluntad de Diospara dar a conoce... | P31: https://watvmedia.org/es/media/jerusalem-mother | Q31: https://youtu.be/XtcsTw2J4oM
A32: =IF('Buscar · Search'!$B$1="","",IF(ISNUMBER(SEARCH('Buscar · Search'!$B$1,$E32&" "&$F32&" "&$G32&" "&$H32&" "&$I32&" "&$J32&" "&$K32&" "&$O32)),"SÍ","")) | B32: 31 | C32: ES | D32: Sermón | E32: Las profecías de los profetas y los pensamientos de la gente del mundo | F32: Sermón | G32: Padre/Madre, Verdad | I32: Cristo Ahnsahnghong y las profecías (70); La Biblia y su autoridad (52); Educación de los hijos y familia (23); Avaricia y materialismo (22); Padre celestial (Cristo Ahnsahnghong) (12); Evangelización y predicación (12); Salvación y vida eterna (9); Familia celestial y Sion (9) | J32: Dios en la carme, Salvación | K32: jesus, profecias, profetas, tierra, epoca, mundo, biblia, pensamientos, vino, hombre, diciendo, camino | L32: 36:55 | M32: 6 nov 2017 | N32: 184.021 | O32: Jesús nació como un niño según la profecía de la Biblia y entró en Jerusalén cabalgando un pollino.Sin embargo, los judíos no podían creer en Él, que vino a la tierra ocultando su naturaleza divina.Po... | P32: https://watvmedia.org/es/media/the-prophecies-of-prophets-the-thoughts-of-people-of-the-world | Q32: https://youtu.be/GTqj5lu2o6Q
A33: =IF('Buscar · Search'!$B$1="","",IF(ISNUMBER(SEARCH('Buscar · Search'!$B$1,$E33&" "&$F33&" "&$G33&" "&$H33&" "&$I33&" "&$J33&" "&$K33&" "&$O33)),"SÍ","")) | B33: 32 | C33: ES | D33: Sermón | E33: Dios Todopoderoso y el mundo de la fe | F33: Sermón | G33: Carácter | I33: Fe y confianza en Dios (76); La Biblia y su autoridad (27); Evangelización y predicación (18); Educación de los hijos y familia (18); Palabras y lengua (hablar bien) (14); Dinero, trabajo y provisión (10); Familia celestial y Sion (9); Cielo, infierno y alma (8) | J33: Resistencia, Humildad | K33: todopoderoso, tierra, aunque, tener, siempre, tiempo, camino, tesoro, omnipotente, poder, tenemos, obra | L33: 41:59 | M33: 3 dic 2018 | N33: 180.114 | O33: La fe después de comprender a Dios correctamente y la obra de DiosCuando solo consideramos nuestra situación, no podemos crecer en la fe sino que llegamos a quejarnos y murmurar. Cuando Gedeón, Job, N... | P33: https://watvmedia.org/es/media/almighty-god-the-world-of-faith | Q33: https://youtu.be/D4ZslvRzYMk
A34: =IF('Buscar · Search'!$B$1="","",IF(ISNUMBER(SEARCH('Buscar · Search'!$B$1,$E34&" "&$F34&" "&$G34&" "&$H34&" "&$I34&" "&$J34&" "&$K34&" "&$O34)),"SÍ","")) | B34: 33 | C34: ES | D34: Sermón | E34: La verdad y la falsedad | F34: Sermón | G34: El nuevo pacto y las fiestas, Verdad | I34: La Biblia y su autoridad (56); Pascua (28); Día de Reposo (sábado) (24); Cristo Ahnsahnghong y las profecías (23); Asistencia al culto y adoración (20); Cielo, infierno y alma (17); Salvación y vida eterna (15); Fe y confianza en Dios (15) | J34: Nuevo pacto, Mandamientos, Discernimiento de la falsedad | K34: jesus, cizana, pascua, reposo, apostoles, sembro, leyes, cielo, trigo, culto, cabeza, cielos | L34: 38:55 | M34: 21 nov 2019 | N34: 172.421 | O34: Hay incontables denominaciones y religiones en este mundo.Cada una de ellas insiste en que su creencia es verdadera.Sin embargo, Jesús distinguió la verdad de la falsedad mediante la parábola de la ci... | P34: https://watvmedia.org/es/media/truth-and-falsehood | Q34: https://youtu.be/_6x2BTVmSnQ
A35: =IF('Buscar · Search'!$B$1="","",IF(ISNUMBER(SEARCH('Buscar · Search'!$B$1,$E35&" "&$F35&" "&$G35&" "&$H35&" "&$I35&" "&$J35&" "&$K35&" "&$O35)),"SÍ","")) | B35: 34 | C35: ES | D35: Sermón | E35: El Salvador y el nombre nuevo | F35: Sermón | G35: Padre/Madre | I35: La Biblia y su autoridad (58); Espíritu Santo y la Esposa (37); Salvación y vida eterna (34); Educación de los hijos y familia (30); Padre celestial (Cristo Ahnsahnghong) (23); Oración (18); Fe y confianza en Dios (14); Cielo, infierno y alma (11) | J35: Padre, Dios en la carme | K35: nombre, jesus, epoca, jehova, espiritu, santo, salvacion, tiempo, biblia, salvador, orar, tiene | L35: 37:03 | M35: 16 jul 2018 | N35: 140.823 | O35: Dios da salvación en el nombre del Padre,del Hijo y del Espíritu SantoAsí como Dios dio diferentes mandamientos sobre la comida en cada época,dio diferentes nombres del Salvadoren la época del Padre, ... | P35: https://watvmedia.org/es/media/the-savior-the-new-name | Q35: https://youtu.be/A05MfufGejo
A36: =IF('Buscar · Search'!$B$1="","",IF(ISNUMBER(SEARCH('Buscar · Search'!$B$1,$E36&" "&$F36&" "&$G36&" "&$H36&" "&$I36&" "&$J36&" "&$K36&" "&$O36)),"SÍ","")) | B36: 35 | C36: ES | D36: Sermón | E36: La parábola de la higuera y Cristo Ahnsahnghong | F36: Sermón | I36: La Biblia y su autoridad (46); Cristo Ahnsahnghong y las profecías (35); Evangelización y predicación (16); Padre celestial (Cristo Ahnsahnghong) (11); Educación de los hijos y familia (7); Salvación y vida eterna (6); El nuevo pacto (6); Amor y palabra de Dios Madre (5) | J36: Padre | K36: higuera, jesus, profecia, parabola, hojas, higos, rama, tierna, israel, tierra, fruto, tiempo | L36: 29:55 | M36: 15 feb 2021 | N36: 123.219 | O36: ¿Quién inició la obra del evangelio en 1948 según la parábola de la higuera?Jesús les dijo a sus discípulos que aprendieran la parábola de la higuera, para hacernos saber el momento exacto en que vend... | P36: https://watvmedia.org/es/media/the-parable-of-the-fig-tree--christ-ahnsahnghong | Q36: https://youtu.be/hLnqYMAdrIk
A37: =IF('Buscar · Search'!$B$1="","",IF(ISNUMBER(SEARCH('Buscar · Search'!$B$1,$E37&" "&$F37&" "&$G37&" "&$H37&" "&$I37&" "&$J37&" "&$K37&" "&$O37)),"SÍ","")) | B37: 36 | C37: ES | D37: Sermón | E37: El que cree y el que no cree | F37: Sermón | G37: Fe, Verdad | I37: La Biblia y su autoridad (55); Educación de los hijos y familia (23); Cristo Ahnsahnghong y las profecías (17); Salvación y vida eterna (12); Padre celestial (Cristo Ahnsahnghong) (12); Palabras y lengua (hablar bien) (9); Espíritu Santo y la Esposa (9); Arrepentimiento (9) | J37: Salvación, Fe | K37: jesus, tierra, vino, biblia, carne, isaias, ojos, creer, apariencia, hombre, veamos, escribieron | L37: 38:12 | M37: 27 dic 2018 | N37: 123.033 | O37: Los miembros de la Iglesia de Dios han recibido a Dios que vino en la carne como lo hizo PedroDios da gracia a los que creen en Él, pero se convierte en un obstáculo para los que dudan o no creen. Nos... | P37: https://watvmedia.org/es/media/he-who-believes-he-who-doesnt | Q37: https://youtu.be/qbSmCxZq1h8
A38: =IF('Buscar · Search'!$B$1="","",IF(ISNUMBER(SEARCH('Buscar · Search'!$B$1,$E38&" "&$F38&" "&$G38&" "&$H38&" "&$I38&" "&$J38&" "&$K38&" "&$O38)),"SÍ","")) | B38: 37 | C38: ES | D38: Sermón | E38: El secreto del perdón de pecados y la Pascua | F38: Sermón | G38: El nuevo pacto y las fiestas | I38: Arrepentimiento (75); La Biblia y su autoridad (64); Cielo, infierno y alma (44); Pascua (32); Salvación y vida eterna (22); Perdón y reconciliación (21); Avaricia y materialismo (9); Familia celestial y Sion (8) | J38: Pascua | K38: tierra, pecados, cielo, pascua, jesus, biblia, vino, muerte, antes, perdon, cuerpo, embargo | L38: 35:13 | M38: 11 mar 2021 | N38: 121.936 | O38: ¿Quién perdona nuestros pecados mediante la Pascua del nuevo pacto?Para salvar a la humanidad que vino a la tierra por cometer en el reino de los cielos pecados que merecen la muerte, Dios mismo vino ... | P38: https://watvmedia.org/es/media/the-secret-of-the-forgiveness-of-sins-the-passover | Q38: https://youtu.be/2uGlLC6qDAE
A39: =IF('Buscar · Search'!$B$1="","",IF(ISNUMBER(SEARCH('Buscar · Search'!$B$1,$E39&" "&$F39&" "&$G39&" "&$H39&" "&$I39&" "&$J39&" "&$K39&" "&$O39)),"SÍ","")) | B39: 38 | C39: ES | D39: Sermón | E39: Prueba | F39: Sermón | G39: Fe | I39: Pruebas y tribulación (39); La Biblia y su autoridad (39); Fe y confianza en Dios (26); Salvación y vida eterna (21); Amor y palabra de Dios Madre (21); Avaricia y materialismo (15); Educación de los hijos y familia (12); Palabras y lengua (hablar bien) (8) | J39: Superando una prueba | K39: prueba, jesus, tierra, vino, conocer, creer, mundo, cielos, pregunta, dificil, eterna, reino | L39: 38:06 | M39: 24 sept 2019 | N39: 118.448 | O39: La fe sincera es la que no vacila en tiempos de dificultades y pruebasA través de la historia de los israelitas que murmuraron y se quejaron contra Dios durante su viaje de cuarenta años en el desiert... | P39: https://watvmedia.org/es/media/test | Q39: https://youtu.be/OvfqC9owxfI
A40: =IF('Buscar · Search'!$B$1="","",IF(ISNUMBER(SEARCH('Buscar · Search'!$B$1,$E40&" "&$F40&" "&$G40&" "&$H40&" "&$I40&" "&$J40&" "&$K40&" "&$O40)),"SÍ","")) | B40: 39 | C40: ES | D40: Sermón | E40: El Padre Ahnsahnghong es Dios, Cristo que vino por segunda vez II | F40: Sermón | G40: Padre/Madre | I40: La Biblia y su autoridad (68); Cristo Ahnsahnghong y las profecías (30); Evangelización y predicación (28); Padre celestial (Cristo Ahnsahnghong) (19); Educación de los hijos y familia (19); Bautismo (19); Juicio y segunda venida (16); El nuevo pacto (9) | J40: Padre, Dios en la carme | K40: jesus, david, tierra, segunda, biblia, venida, escrito, israel, evangelio, higuera, despues, pacto | L40: 36:10 | M40: 22 oct 2021 | N40: 117.483 | O40: Respecto a la pregunta: “El Señor Ahnsahnghong es un hombre. ¿Cómo puede ser Dios?”Cristo Ahnsahnghong es Dios porque solo Él es la raíz de David que vino en los últimos días y restauró el pacto etern... | P40: https://watvmedia.org/es/media/father-ahnsahnghong-is-god-christ-who-came-a-second-time-ii | Q40: https://youtu.be/HkdkaXYmtwg
A41: =IF('Buscar · Search'!$B$1="","",IF(ISNUMBER(SEARCH('Buscar · Search'!$B$1,$E41&" "&$F41&" "&$G41&" "&$H41&" "&$I41&" "&$J41&" "&$K41&" "&$O41)),"SÍ","")) | B41: 40 | C41: ES | D41: Sermón | E41: La Pascua y el Orden de Melquisedec | F41: Sermón | G41: El nuevo pacto y las fiestas | I41: Pascua (39); La Biblia y su autoridad (39); Salvación y vida eterna (27); El nuevo pacto (21); Servicio y sacrificio (18); Arrepentimiento (15); Perdón y reconciliación (12); Cena del Señor / Santa Cena (12) | J41: Nuevo pacto, Pascua | K41: melquisedec, orden, pacto, pascua, sangre, vino, traves, esto, jesus, sacerdote, sacerdocio, sacrificio | L41: 28:34 | M41: 23 nov 2017 | N41: 117.217 | O41: ¿Qué tipo de culto complace a Dios como el sacrificio de Abel?El orden de Melquisedec a través de la Pascua del nuevo pactoes el sacrificio invariable que Dios mismo estableció en la tierrapara que no... | P41: https://watvmedia.org/es/media/the-passover-the-order-of-melchizedek | Q41: https://youtu.be/DqVDdA60LgM
A42: =IF('Buscar · Search'!$B$1="","",IF(ISNUMBER(SEARCH('Buscar · Search'!$B$1,$E42&" "&$F42&" "&$G42&" "&$H42&" "&$I42&" "&$J42&" "&$K42&" "&$O42)),"SÍ","")) | B42: 41 | C42: ES | D42: Sermón | E42: ¿Por qué los hombres no pueden recordar el mundo anterior? | F42: Sermón | G42: Verdad | I42: Avaricia y materialismo (26); Padre celestial (Cristo Ahnsahnghong) (17); La Biblia y su autoridad (17); Cielo, infierno y alma (16); Salvación y vida eterna (15); Educación de los hijos y familia (15); Arrepentimiento (13); Amor y palabra de Dios Madre (7) | J42: Profecía | K42: mundo, reino, tierra, celestial, espiritu, principes, cielos, nobles, princesas, satanas, carne, anterior | L42: 23:26 | M42: 23 ene 2018 | N42: 112.214 | O42: Cristo Ahnsahnghong escribió en su libro Los Visitantes del Mundo Angelical, que los seres humanos eran nobles ángeles del cielo, pero cometieron pecadosy fueron arrojados a esta tierra, completamente... | P42: https://watvmedia.org/es/media/why-does-man-not-remember-his-previous-life | Q42: https://youtu.be/8wLIqAgnjgs
A43: =IF('Buscar · Search'!$B$1="","",IF(ISNUMBER(SEARCH('Buscar · Search'!$B$1,$E43&" "&$F43&" "&$G43&" "&$H43&" "&$I43&" "&$J43&" "&$K43&" "&$O43)),"SÍ","")) | B43: 42 | C43: ES | D43: Sermón | E43: Búscame | F43: Sermón | G43: Padre/Madre | I43: La Biblia y su autoridad (57); Padre celestial (Cristo Ahnsahnghong) (49); Amor y palabra de Dios Madre (45); Educación de los hijos y familia (32); Salvación y vida eterna (19); Cristo Ahnsahnghong y las profecías (19); Cielo, infierno y alma (11); Espíritu Santo y la Esposa (10) | J43: Madre, Dios en la carme | K43: pensamientos, biblia, espiritu, jesus, buscar, esposa, veamos, hombre, embargo, somos, tenemos, tener | L43: 32:40 | M43: 23 ene 2018 | N43: 108.735 | O43: Cuando los 300 guerreros de Gedeón derrotaron a 135 000 madianitas,el ejército de Gedeón ganó una victoria gracias a la obra de Dios.Del mismo modo, hay una gran diferenciaentre los pensamientos de Di... | P43: https://watvmedia.org/es/media/seek-me | Q43: https://youtu.be/-pbiFTBl-bo
A44: =IF('Buscar · Search'!$B$1="","",IF(ISNUMBER(SEARCH('Buscar · Search'!$B$1,$E44&" "&$F44&" "&$G44&" "&$H44&" "&$I44&" "&$J44&" "&$K44&" "&$O44)),"SÍ","")) | B44: 43 | C44: ES | D44: Sermón | E44: Dios, la fuente de la sabiduría | F44: Sermón | G44: Padre/Madre, El nuevo pacto y las fiestas, Verdad | I44: La Biblia y su autoridad (67); Salvación y vida eterna (35); Avaricia y materialismo (15); Fiestas solemnes de Dios (14); Familia celestial y Sion (14); Pascua (11); Amor y palabra de Dios Madre (10); Padre celestial (Cristo Ahnsahnghong) (9) | J44: Madre, Dios Elohim, Nuevo pacto, Pascua, Sion, Salvación | K44: sabiduria, biblia, salvacion, carne, habitacion, encontrar, conocimiento, mundo, tierra, sion, jesus, eterna | L44: 38:39 | M44: 26 nov 2019 | N44: 107.899 | O44: Mediante la historia de un rey que quería encontrar un siervo sabio, y la sabiduría de Zhuge Liang, podemos ver que la sabiduría es algo provechoso que nos permite superar las dificultades de la vida.... | P44: https://watvmedia.org/es/media/god-the-source-of-wisdom | Q44: https://youtu.be/vKl9sIzgwG0
A45: =IF('Buscar · Search'!$B$1="","",IF(ISNUMBER(SEARCH('Buscar · Search'!$B$1,$E45&" "&$F45&" "&$G45&" "&$H45&" "&$I45&" "&$J45&" "&$K45&" "&$O45)),"SÍ","")) | B45: 44 | C45: ES | D45: Sermón | E45: La Madre Jerusalén y la vida eterna | F45: Sermón | G45: Padre/Madre | I45: La Biblia y su autoridad (68); Salvación y vida eterna (51); Amor y palabra de Dios Madre (39); Educación de los hijos y familia (31); La creación y el diseño de Dios (15); Cielo, infierno y alma (13); Fe y confianza en Dios (10); Avaricia y materialismo (8) | J45: Madre | K45: eterna, biblia, madres, traves, tiene, creo, imagen, voluntad, postrero, esposa, tener, jesus | L45: 38:23 | M45: 30 oct 2018 | N45: 107.836 | O45: Todas las cosas creadas por Dios son como un libro que nos enseña el mundo espiritualDios creó a Eva (vida) en el sexto día de su obra de la creación, y dejó que todos los seres recibieran vida de sus... | P45: https://watvmedia.org/es/media/jerusalem-mother-eternal-life | Q45: https://youtu.be/0VeLCei_piM
A46: =IF('Buscar · Search'!$B$1="","",IF(ISNUMBER(SEARCH('Buscar · Search'!$B$1,$E46&" "&$F46&" "&$G46&" "&$H46&" "&$I46&" "&$J46&" "&$K46&" "&$O46)),"SÍ","")) | B46: 45 | C46: ES | D46: Sermón | E46: Una vida valiosa | F46: Sermón | G46: Fe | I46: Educación de los hijos y familia (30); La Biblia y su autoridad (23); Cielo, infierno y alma (20); Fe y confianza en Dios (18); Avaricia y materialismo (10); El nuevo pacto (9); Salvación y vida eterna (8); Padre celestial (Cristo Ahnsahnghong) (6) | J46: Predicación | K46: tierra, valiosa, cielo, siempre, testigos, padres, mundo, vivir, entender, eterno, pacto, reino | L46: 34:41 | M46: 16 ene 2020 | N46: 105.602 | O46: Las piedras que tenían valor antes de la civilización, no tienen valor en las sociedades modernas.Del mismo modo, hay una gran diferencia de valorentre las cosas terrenales y las cosas celestiales. Se... | P46: https://watvmedia.org/es/media/valuable-life | Q46: https://youtu.be/ah62NGEEoa4
A47: =IF('Buscar · Search'!$B$1="","",IF(ISNUMBER(SEARCH('Buscar · Search'!$B$1,$E47&" "&$F47&" "&$G47&" "&$H47&" "&$I47&" "&$J47&" "&$K47&" "&$O47)),"SÍ","")) | B47: 46 | C47: ES | D47: Sermón | E47: La Biblia Verdadera | F47: Sermón | G47: Verdad | I47: La Biblia y su autoridad (87); Palabras y lengua (hablar bien) (29); Cristo Ahnsahnghong y las profecías (26); Salvación y vida eterna (10); Asistencia al culto y adoración (10); Cielo, infierno y alma (9); Avaricia y materialismo (9); Arrepentimiento (5) | J47: Biblia | K47: biblia, tierra, siro, esto, imperio, agua, ciencia, persia, daniel, israelitas, despues, jehova | L47: 37:30 | M47: 23 nov 2017 | N47: 104.994 | O47: Dios Padre y Dios Madre guían cada época y la historiaA través de los registros bíblicos que preceden a la cienciay la historia del mundo que se desarrollaron de acuerdo con la palabra de Dios,podemos... | P47: https://watvmedia.org/es/media/the-true-bible | Q47: https://youtu.be/iZVtTHLO-qc
A48: =IF('Buscar · Search'!$B$1="","",IF(ISNUMBER(SEARCH('Buscar · Search'!$B$1,$E48&" "&$F48&" "&$G48&" "&$H48&" "&$I48&" "&$J48&" "&$K48&" "&$O48)),"SÍ","")) | B48: 47 | C48: ES | D48: Sermón | E48: Si conocen, amarán | F48: Sermón | G48: Padre/Madre, Fe | I48: La Biblia y su autoridad (52); Padre celestial (Cristo Ahnsahnghong) (34); Educación de los hijos y familia (34); Amor y palabra de Dios Madre (27); Evangelización y predicación (13); Cielo, infierno y alma (12); Avaricia y materialismo (9); Amor y amor fraternal (9) | J48: Dios Elohim, Predicación | K48: conocer, jesus, hormigas, biblia, pablo, jerusalen, conocemos, despues, tierra, antes, escrito, hormiga | L48: 39:42 | M48: 27 may 2019 | N48: 101.209 | O48: Cuanto más aprende sobre Dios, más llega a amarloPodemos llegar a amar a Dios cuando aprendemos correctamente sobre Él, al igual que el entomólogo que llegó a amar a las hormigas que había odiado ante... | P48: https://watvmedia.org/es/media/if-you-know-you-will-love | Q48: https://youtu.be/APvRsKIPbQQ
... A97: =IF('Buscar · Search'!$B$1="","",IF(ISNUMBER(SEARCH('Buscar · Search'!$B$1,$E97&" "&$F97&" "&$G97&" "&$H97&" "&$I97&" "&$J97&" "&$K97&" "&$O97)),"SÍ","")) | B97: 96 | C97: ES | D97: Sermón | E97: Vayamos al glorioso reino de Dios | F97: Sermón | G97: Fe, Verdad | I97: La Biblia y su autoridad (76); Humildad y orgullo (48); Dinero, trabajo y provisión (28); Cielo, infierno y alma (27); Salvación y vida eterna (22); Avaricia y materialismo (21); Pruebas y tribulación (12); Educación de los hijos y familia (7) | J97: Alma, Esperanza | K97: vanidad, tierra, cielo, esto, reino, mundo, hombre, cielos, trabajo, vayamos, despues, manos | L97: 34:29 | M97: 25 ene 2021 | N97: 64.274 | O97: La confesión de Salomón:“Todo debajo del sol es vanidad”.Dios nos ha enseñado mediante Salomón que todaslas cosas debajo del sol se desvanecen en un instante;son vanidad, y aflicción de espíritu.Para ... | P97: https://watvmedia.org/es/media/let-us-go-toward-the-glorious-kingdom-of-god | Q97: https://youtu.be/HWSgGdyfwr0
A98: =IF('Buscar · Search'!$B$1="","",IF(ISNUMBER(SEARCH('Buscar · Search'!$B$1,$E98&" "&$F98&" "&$G98&" "&$H98&" "&$I98&" "&$J98&" "&$K98&" "&$O98)),"SÍ","")) | B98: 97 | C98: ES | D98: Sermón | E98: La Madre Celestial Jerusalén | F98: Sermón | G98: Padre/Madre | H98: Mother | I98: La Biblia y su autoridad (70); Amor y palabra de Dios Madre (63); Educación de los hijos y familia (57); Salvación y vida eterna (38); Avaricia y materialismo (21); Padre celestial (Cristo Ahnsahnghong) (16); Palabras y lengua (hablar bien) (14); La creación y el diseño de Dios (13) | J98: Madre, Dios Elohim | K98: celestial, eterna, creo, biblia, voluntad, promesa, mundo, esposa, cordero, tierra, jerusalen, existe | L98: 32:59 | M98: 17 may 2022 | N98: 64.082 | O98: ¿Cómo podemos convertirnos en “los hijos de la promesa” que han recibido la vida eterna de Dios?La razón de que las efímeras vivan solo un día, los perros quince años, y los humanos cien años es que h... | P98: https://watvmedia.org/es/media/heavenly-mother-jerusalem | Q98: https://youtu.be/2Ep2owiC4hA
A99: =IF('Buscar · Search'!$B$1="","",IF(ISNUMBER(SEARCH('Buscar · Search'!$B$1,$E99&" "&$F99&" "&$G99&" "&$H99&" "&$I99&" "&$J99&" "&$K99&" "&$O99)),"SÍ","")) | B99: 98 | C99: ES | D99: Sermón | E99: Acerca del alma (2) | F99: Sermón | G99: Fe, Verdad | I99: Cielo, infierno y alma (48); Avaricia y materialismo (44); La Biblia y su autoridad (42); Educación de los hijos y familia (19); Salvación y vida eterna (10); Padre celestial (Cristo Ahnsahnghong) (8); Esperanza y consuelo (8); Resurrección y transformación (6) | J99: Alma, Esperanza | K99: mundo, alma, tierra, cuerpo, jesus, espiritual, esto, existe, embargo, biblia, experimentado, creer | L99: 32:08 | M99: 10 abr 2020 | N99: 63.456 | O99: La humanidad pecó en el cielo y vino a esta tierraSi comprendemos el asunto del alma,podemos saber cuál es la razón de la creación de los cielos y la tierra y por qué estamos viviendo en la tierra, y ... | P99: https://watvmedia.org/es/media/about-the-soul2 | Q99: https://youtu.be/YJRR-_nQygI
A100: =IF('Buscar · Search'!$B$1="","",IF(ISNUMBER(SEARCH('Buscar · Search'!$B$1,$E100&" "&$F100&" "&$G100&" "&$H100&" "&$I100&" "&$J100&" "&$K100&" "&$O100)),"SÍ","")) | B100: 99 | C100: ES | D100: Sermón | E100: El corazón de los Padres celestiales | F100: Sermón | G100: Padre/Madre | I100: Educación de los hijos y familia (113); Amor y amor fraternal (21); Pruebas y tribulación (16); La Biblia y su autoridad (13); El nuevo pacto (13); Cielo, infierno y alma (10); Salvación y vida eterna (8); Amor y palabra de Dios Madre (8) | J100: Padre, Madre, Dios Elohim, Sacrificio de Dios | K100: padres, amor, celestiales, pacto, camino, tierra, campesino, familia, cielo, aunque, dificultades, esposa | L100: 24:45 | M100: 23 ene 2018 | N100: 63.401 | O100: Así como los israelitas atravesaron muchas dificultades, pruebas y trampas en el desierto hacia Canaán, nosotros también podríamos tener dificultades y pruebas en el desierto de la fe. Dios quiere dar... | P100: https://watvmedia.org/es/media/the-heart-of-heavenly-parents | Q100: https://youtu.be/E7f6Uvg9-Rk
A101: =IF('Buscar · Search'!$B$1="","",IF(ISNUMBER(SEARCH('Buscar · Search'!$B$1,$E101&" "&$F101&" "&$G101&" "&$H101&" "&$I101&" "&$J101&" "&$K101&" "&$O101)),"SÍ","")) | B101: 100 | C101: ES | D101: Sermón | E101: Los mandamientos de Dios y el camino de la salvación | F101: Sermón | G101: El nuevo pacto y las fiestas | I101: La Biblia y su autoridad (30); Cielo, infierno y alma (30); Padre celestial (Cristo Ahnsahnghong) (18); Dinero, trabajo y provisión (15); Día de Reposo (sábado) (14); Educación de los hijos y familia (13); El nuevo pacto (12); Salvación y vida eterna (11) | J101: Mandamientos | K101: leyes, tierra, estatutos, ordenanzas, pacto, mandamientos, reposo, cielo, infierno, jehova, esto, dinero | L101: 30:23 | M101: 18 dic 2020 | N101: 63.356 | O101: Guardar los mandamientos de Dios es el camino de la salvaciónSatanás primero destruyó el Día de Reposo, el mandamiento de Dios, que es el camino de la salvación.Después, cuando desaparecieron todas la... | P101: https://watvmedia.org/es/media/gods-commandments-and-the-way-of-salvation | Q101: https://youtu.be/VqHgjbFP_VA
A102: =IF('Buscar · Search'!$B$1="","",IF(ISNUMBER(SEARCH('Buscar · Search'!$B$1,$E102&" "&$F102&" "&$G102&" "&$H102&" "&$I102&" "&$J102&" "&$K102&" "&$O102)),"SÍ","")) | B102: 101 | C102: ES | D102: Sermón | E102: Las Escrituras dicen que es necesario que así se haga | F102: Sermón | G102: Fe | I102: La Biblia y su autoridad (95); Educación de los hijos y familia (73); Padre celestial (Cristo Ahnsahnghong) (45); Amor y palabra de Dios Madre (38); Pascua (31); Avaricia y materialismo (14); Palabras y lengua (hablar bien) (12); Cielo, infierno y alma (9) | J102: Fe | K102: biblia, pascua, esto, familia, sangre, jesus, tierra, celestial, existe, figura, hombre, hagamos | L102: 36:11 | M102: 23 nov 2017 | N102: 63.219 | O102: La Biblia testifica que Dios vino a salvar a la humanidad.Podemos reconocer a Dios, que vino a salvarnos, si vemos la Biblia sin añadir nuestros pensamientos.La Biblia da a conocer a Dios MadreMuchos ... | P102: https://watvmedia.org/es/media/the-scriptures-that-say-it-must-happen-in-this-way | Q102: https://youtu.be/AoMWqbTfjfA
...

Sheet Temas · Topics
A1: Idioma | B1: Tema / Topic | C1: Nº | D1: Título / Title | E1: Tipo | F1: Duración | G1: Fecha | H1: Menciones | I1: Enlace / Link
A2: ES | B2: Alegría y felicidad | C2: 1 | D2: El secreto de la felicidad y el reino de los cielos | E2: Sermón | F2: 32:35 | G2: 19 ago 2022 | H2: 40 | I2: https://watvmedia.org/es/media/the-secret-to-happiness-the-kingdom-of-heaven
A3: ES | B3: Alegría y felicidad | C3: 2 | D3: Dios prueba los corazones | E3: Sermón | F3: 30:08 | G3: 11 feb 2022 | H3: 22 | I3: https://watvmedia.org/es/media/god-tests-the-heart
A4: ES | B4: Alegría y felicidad | C4: 3 | D4: La ley de Dios y el fruto de los pensamientos | E4: Sermón | F4: 30:53 | G4: 7 mar 2025 | H4: 20 | I4: https://watvmedia.org/es/media/the-results-of-gods-law-and-thoughts
A5: ES | B5: Alegría y felicidad | C5: 4 | D5: Separados de Dios, no podemos vivir | E5: Sermón | F5: 37:01 | G5: 22 dic 2023 | H5: 19 | I5: https://watvmedia.org/es/media/you-cant-live-without-god
A6: ES | B6: Alegría y felicidad | C6: 5 | D6: Para a la postre hacerte bien | E6: Sermón | F6: 34:02 | G6: 3 jul 2026 | H6: 17 | I6: https://watvmedia.org/es/media/god-wants-to-bless-him-in-the-end
A7: ES | B7: Alegría y felicidad | C7: 6 | D7: La Fiesta de los Panes sin Levadura y la evangelización mundial | E7: Sermón | F7: 29:28 | G7: 15 abr 2022 | H7: 16 | I7: https://watvmedia.org/es/media/the-feast-of-unleavened-bread-and-world-evangelism
A8: ES | B8: Alegría y felicidad | C8: 7 | D8: Anhelo por la eternidad | E8: Sermón | F8: 31:14 | G8: 23 mar 2024 | H8: 15 | I8: https://watvmedia.org/es/media/a-heart-that-longs-for-eternity
A9: ES | B9: Alegría y felicidad | C9: 8 | D9: Estad siempre gozosos | E9: Mensual | F9: 08:06 | G9: 3 jul 2025 | H9: 13 | I9: https://watvmedia.org/es/media/always-be-happy
A10: ES | B10: Alegría y felicidad | C10: 9 | D10: Los placeres del pecado y los placeres del cielo | E10: Sermón | F10: 31:55 | G10: 9 jul 2026 | H10: 13 | I10: https://watvmedia.org/es/media/the-pleasures-of-sin-and-the-pleasures-of-heaven
A11: ES | B11: Alegría y felicidad | C11: 10 | D11: ¿Quién soy? | E11: Sermón | F11: 27:31 | G11: 4 ago 2023 | H11: 12 | I11: https://watvmedia.org/es/media/who-am-i
A12: ES | B12: Alegría y felicidad | C12: 11 | D12: Dios Madre, la Arquitecta de la vida | E12: Sermón | F12: 20:25 | G12: 13 nov 2023 | H12: 11 | I12: https://watvmedia.org/es/media/god-the-mother-the-architect-of-life
A13: ES | B13: Alegría y felicidad | C13: 12 | D13: El corazón de la Madre y Sion | E13: Sermón | F13: 30:32 | G13: 23 ene 2018 | H13: 10 | I13: https://watvmedia.org/es/media/mothers-heart-zion
... A5845: ES | B5845: Unidad y armonía | C5845: 13 | D5845: Seamos uno | E5845: Resumen | F5845: 04:10 | G5845: 19 feb 2026 | H5845: 3 | I5845: https://watvmedia.org/es/media/lets-become-one
A5846: EN | B5846: Anger and temper | C5846: 1 | D5846: The Way Back to Heaven | E5846: Sermón | F5846: 35:07 | H5846: 26 | I5846: https://watvmedia.org/en/media/the-way-back-to-heaven
A5847: EN | B5847: Anger and temper | C5847: 2 | D5847: Words that Bring Blessings | E5847: Sermón | F5847: 31:21 | H5847: 22 | I5847: https://watvmedia.org/en/media/words-that-bring-blessings
A5848: EN | B5848: Anger and temper | C5848: 3 | D5848: Day of Judgment & Day of Salvation | E5848: Sermón | F5848: 30:40 | H5848: 20 | I5848: https://watvmedia.org/en/media/day-of-judgment-day-of-salvation
A5849: EN | B5849: Anger and temper | C5849: 4 | D5849: Words Leading to Blessings | E5849: Sermón | F5849: 29:10 | H5849: 19 | I5849: https://watvmedia.org/en/media/words-that-lead-to-blessings
A5850: EN | B5850: Anger and temper | C5850: 5 | D5850: Bad Habits & Good Habits | E5850: Sermón | F5850: 37:11 | H5850: 15 | I5850: https://watvmedia.org/en/media/bad-habits-good-habits
A5851: EN | B5851: Anger and temper | C5851: 6 | D5851: Do Not Put God to the Test | E5851: Sermón | F5851: 32:04 | H5851: 14 | I5851: https://watvmedia.org/en/media/do-not-put-god-to-the-test
A5852: EN | B5852: Anger and temper | C5852: 7 | D5852: Heavenly Language | E5852: Sermón | F5852: 28:54 | H5852: 14 | I5852: https://watvmedia.org/en/media/language-of-heaven
A5853: EN | B5853: Anger and temper | C5853: 8 | D5853: The Commandment of Love | E5853: Sermón | F5853: 29:13 | H5853: 14 | I5853: https://watvmedia.org/en/media/the-commandment-of-love
A5854: EN | B5854: Anger and temper | C5854: 9 | D5854: God the Savior of Our Life | E5854: Sermón | F5854: 36:13 | H5854: 13 | I5854: https://watvmedia.org/en/media/god-the-savior-of-our-life
A5855: EN | B5855: Anger and temper | C5855: 10 | D5855: Longing for Eternity | E5855: Sermón | F5855: 31:14 | H5855: 13 | I5855: https://watvmedia.org/en/media/a-heart-that-longs-for-eternity
A5856: EN | B5856: Anger and temper | C5856: 11 | D5856: The Festival of Trumpets & the Trumpet of Repentance | E5856: Sermón | F5856: 29:51 | H5856: 12 | I5856: https://watvmedia.org/en/media/the-feast-of-trumpets-and-the-trumpet-of-repentance
A5857: EN | B5857: Anger and temper | C5857: 12 | D5857: The Focus of Life & Gratitude | E5857: Sermón | F5857: 31:55 | H5857: 11 | I5857: https://watvmedia.org/en/media/the-focus-of-life--gratitude
... A12253: EN | B12253: Worship and service attendance | C12253: 98 | D12253: What Day of the Week Is the Sabbath Day of the New Covenant? | E12253: Resumen | F12253: 08:31 | H12253: 3 | I12253: https://watvmedia.org/en/media/what-day-of-the-week-is-the-sabbath-day-of-the-new-covenant

Sheet Mensual · Monthly
A1: Idioma | B1: Título / Title | C1: Duración | D1: Fecha | E1: Temas / Topics | F1: Enlace / Link
A2: ES | B2: Deben nacer de nuevo para entrar en el Reino de los Cielos | C2: 05:24 | D2: 14 dic 2023 | E2: Amor y amor fraternal; Cielo, infierno y alma; Educación de los hijos y familia; Salvación y vida eterna; Evangelización y predicación; Avaricia y materialismo; Arrepentimiento | F2: https://watvmedia.org/es/media/be-born-again
A3: ES | B3: Nuestra patria es el cielo: somos extranjeros sobre la tierra | C3: 06:49 | D3: 5 mar 2025 | E3: Cielo, infierno y alma; Salvación y vida eterna; Educación de los hijos y familia; Arrepentimiento; Padre celestial (Cristo Ahnsahnghong); Avaricia y materialismo; Familia celestial y Sion; Enfermedad y sanidad | F3: https://watvmedia.org/es/media/our-home-is-heaven-we-are-strangers-in-this-world
A4: ES | B4: El lino fino de Dios | C4: 08:02 | D4: 30 abr 2025 | E4: Amor y amor fraternal; Salvación y vida eterna; Avaricia y materialismo; Palabras y lengua (hablar bien); Pascua; La Biblia y su autoridad; Ira y enojo (control del temperamento); Educación de los hijos y familia | F4: https://watvmedia.org/es/media/gods-linen
A5: ES | B5: Una fe que practica la unidad | C5: 07:10 | D5: 18 oct 2024 | E5: Cielo, infierno y alma; Unidad y armonía; Salvación y vida eterna; Perdón y reconciliación; Pruebas y tribulación; Evangelización y predicación; Enfermedad y sanidad | F5: https://watvmedia.org/es/media/united-faith
A6: ES | B6: Edifiquemos a los demás con palabras amables y hermosas | C6: 07:34 | D6: 17 jun 2025 | E6: Palabras y lengua (hablar bien); Salvación y vida eterna; Educación de los hijos y familia; Ira y enojo (control del temperamento); Fe y confianza en Dios; Alegría y felicidad; Humildad y orgullo | F6: https://watvmedia.org/es/media/let-us-bestow-grace-with-good-and-beautiful-words
A7: ES | B7: ¿Haciendo qué cosa heredaré la vida eterna? | C7: 06:53 | D7: 22 oct 2024 | E7: Amor y amor fraternal; Cielo, infierno y alma; Salvación y vida eterna; Padre celestial (Cristo Ahnsahnghong); Evangelización y predicación; Pascua; Palabras y lengua (hablar bien) | F7: https://watvmedia.org/es/media/how-eternal-life
A8: ES | B8: Las cosas buenas y las cosas malas | C8: 06:04 | D8: 24 ene 2025 | E8: Cielo, infierno y alma; Educación de los hijos y familia; Perdón y reconciliación; Palabras y lengua (hablar bien); Amor y amor fraternal; Arrepentimiento; Salvación y vida eterna | F8: https://watvmedia.org/es/media/the-good-and-the-bad
A9: ES | B9: Conformarse a las sanas palabras y a la doctrina que es conforme a la piedad | C9: 07:05 | D9: 22 nov 2024 | E9: Educación de los hijos y familia; Cielo, infierno y alma; Salvación y vida eterna; La Biblia y su autoridad; Palabras y lengua (hablar bien); Amor y amor fraternal | F9: https://watvmedia.org/es/media/focus-on-reverence-and-the-word
A10: ES | B10: Todas las naciones correrán a Sion por el camino de la vida | C10: 06:58 | D10: 5 dic 2024 | E10: Salvación y vida eterna; Familia celestial y Sion; Pascua; Fiestas solemnes de Dios; La Biblia y su autoridad; Evangelización y predicación; El nuevo pacto | F10: https://watvmedia.org/es/media/all-nations-find-their-way-to-zion
A11: ES | B11: Según las palabras de la profecía | C11: 06:23 | D11: 22 nov 2024 | E11: Salvación y vida eterna; Cristo Ahnsahnghong y las profecías; La Biblia y su autoridad; Palabras y lengua (hablar bien); Pascua; Cielo, infierno y alma; Arrepentimiento; Familia celestial y Sion | F11: https://watvmedia.org/es/media/words-of-prophecy
A12: ES | B12: Mirad, velad y orad | C12: 05:51 | D12: 24 ene 2025 | E12: Salvación y vida eterna; Padre celestial (Cristo Ahnsahnghong); Educación de los hijos y familia; Pascua; Cristo Ahnsahnghong y las profecías | F12: https://watvmedia.org/es/media/be-careful-stay-awake
... A28: ES | B28: La felicidad de los ciudadanos celestiales | C28: 07:15 | D28: 17 sept 2026 | E28: Educación de los hijos y familia; Amor y amor fraternal; Salvación y vida eterna; Alegría y felicidad; Cielo, infierno y alma; Padre celestial (Cristo Ahnsahnghong); Evangelización y predicación; Espíritu Santo y la Esposa | F28: https://watvmedia.org/es/media/heavenly-citizens-happiness
A29: EN | B29: You Will Reap What You Sow | C29: 06:25 | E29: Love and brotherly love; Heavenly family and Zion; Evangelism and preaching; Words and the tongue; Passover; Heaven, hell and the soul; Anger and temper | F29: https://watvmedia.org/en/media/you-will-reap-what-you-sow
A30: EN | B30: The Word of God Will Stand Forever | C30: 06:52 | E30: Heaven, hell and the soul; Salvation and eternal life; Joy and happiness; Words and the tongue; Hope and comfort; Trials and suffering; Faith and trust in God | F30: https://watvmedia.org/en/media/word-of-god-will-stand-forever
A31: EN | B31: The Happiness of Heavenly Citizens | C31: 07:15 | E31: Love and brotherly love; Heaven, hell and the soul; Children and family; Salvation and eternal life; Joy and happiness; Evangelism and preaching; Words and the tongue; Holy Spirit and the Bride | F31: https://watvmedia.org/en/media/heavenly-citizens-happiness
A32: EN | B32: Achieve Perfect Love | C32: 06:56 | E32: Heaven, hell and the soul; Love and brotherly love; Salvation and eternal life; Prayer; Evangelism and preaching; Children and family; Service and sacrifice; Trials and suffering | F32: https://watvmedia.org/en/media/be-perfect-in-love
A33: EN | B33: Our Citizenship Is in Heaven | C33: 07:36 | E33: Heaven, hell and the soul; Salvation and eternal life; Evangelism and preaching; Children and family; The Bible and its authority; Patience and self-control; Words and the tongue; The new covenant | F33: https://watvmedia.org/en/media/our-citizenship-is-in-heaven1
A34: EN | B34: Be Ready and Preach the Gospel | C34: 07:11 | E34: Evangelism and preaching; Heaven, hell and the soul; Salvation and eternal life; Heavenly family and Zion; Love and brotherly love; Children and family; Passover; Money, work and provision | F34: https://watvmedia.org/en/media/be-ready-preach-the-gospel
A35: EN | B35: The Necessity of the Holy Spirit | C35: 06:42 | E35: Holy Spirit and the Bride; Salvation and eternal life; Heaven, hell and the soul; Evangelism and preaching; Words and the tongue; Obedience; Faith and trust in God | F35: https://watvmedia.org/en/media/the-necessity-of-the-holy-spirit-1
A36: EN | B36: The Fruit of Love Brought Forth Through Humility | C36: 07:38 | E36: Love and brotherly love; Humility and pride; Words and the tongue; Heaven, hell and the soul; Heavenly family and Zion; Children and family; Salvation and eternal life; Money, work and provision | F36: https://watvmedia.org/en/media/channel-video-688589
A37: EN | B37: Autumn Trees Bearing Fruit | C37: 07:40 | E37: Words and the tongue; Heavenly family and Zion; Heaven, hell and the soul; Evangelism and preaching; Salvation and eternal life; The Bible and its authority; Prophecy and Christ Ahnsahnghong; Money, work and provision | F37: https://watvmedia.org/en/media/autumn-tree-bearing-fruits
A38: EN | B38: Live Peacefully With Each Other in Love | C38: 07:38 | E38: Heaven, hell and the soul; Evangelism and preaching; Heavenly family and Zion; Unity and harmony; Salvation and eternal life; Love and brotherly love; Humility and pride; Words and the tongue | F38: https://watvmedia.org/en/media/channel-video-751171
A39: EN | B39: The Faith That Reveres God | C39: 08:52 | E39: Words and the tongue; Salvation and eternal life; Heaven, hell and the soul; Faith and trust in God; Heavenly family and Zion | F39: https://watvmedia.org/en/media/faith-that-fears-god
A40: EN | B40: Rejoice Always | C40: 08:05 | E40: Joy and happiness; Salvation and eternal life; Heaven, hell and the soul; Evangelism and preaching; Holy Spirit and the Bride; Prayer; Heavenly family and Zion; Children and family | F40: https://watvmedia.org/en/media/always-be-happy
... A56: EN | B56: You Must Be Born Again to Enter the Kingdom of Heaven | C56: 05:26 | E56: Love and brotherly love; Heaven, hell and the soul; Children and family; Salvation and eternal life; Evangelism and preaching; Words and the tongue; Trials and suffering; Joy and happiness | F56: https://watvmedia.org/en/media/be-born-again

Sheet Etiquetas · Tags
A1: Idioma | B1: Etiqueta / Tag | C1: Nº | D1: Títulos / Titles
A2: ES | B2: Fe | C2: 184 | D2: Superemos la tentación y obtengamos el reino de los cielos | El que cree y el que no cree | La fe cambia al mundo | La petición del Padre: “Vivan para la misión” | La vida y la muerte, y el camino de la vida eterna | Dios es la respuesta | No tentarás a Dios | En Él que me fortalece | Nunca digan no | El camino celestial que recorremos por la fe | Las Escrituras dicen que es necesario que así se haga | El valor del cielo y el valor del mundo | En verdad, qué benditos | Esfuérzate y sé valiente | Este es el problema | Los que no conocen el valor no tienen derecho a poseerlo | La tentación y la victoria | El mundo invisible y la verdadera fe | Hagan como la Biblia instruye | La fe en Dios | Retribuyamos la gracia de Dios | La familia celestial y jactarse de Dios | La salvación concedida a los que perseveren hasta el fin | Sé celoso, porque el reino de los cielos se ha acercado | Dios puede hacerlo todo
A3: ES | B3: Nuevo pacto | C3: 167 | D3: La verdad y la falsedad | La Pascua y el Orden de Melquisedec | Dios, la fuente de la sabiduría | El Salvador de cada época y el nombre nuevo | La bendición de Dios y el Día de Reposo | El rey David y el nuevo pacto | El día del juicio | La sal y la luz del mundo La vida de un cristiano | Cristo Ahnsahnghong y las profecías | La ciudad de refugio y la tierra | La iglesia establecida por la raíz de David y la verdad del nuevo pacto | La tierra, la ciudad de refugio, y el sistema del nuevo pacto | El rey David y Cristo Ahnsahnghong | La prueba de que somos hijos de Dios | El Espíritu y la Esposa nos llaman | Cuando Israel era fuerte y cuando Israel era débil | El maná escondido y el nombre nuevo | ¿Qué es lo más valioso en el cielo? | Enseñad lo que os he mandado | Una vida sin respuestas | Una convocación repentina | La verdad del árbol de la vida | Los que pueden oír correctamente la voz de Dios | Las características del cristianismo auténtico y de la herejía | La comida dada por Dios
A4: ES | B4: Salvación | C4: 133 | D4: Las profecías de los profetas y los pensamientos de la gente del mundo | El que cree y el que no cree | Dios, la fuente de la sabiduría | Desechemos la arrogancia y seamos humildes | El cielo o el infierno según nuestras obras | ¡Qué hermoso será! | Nuestra Madre Celestial II | Cuando la vida no tiene sentido | El rey David y Cristo Ahnsahnghong | La prueba de que somos hijos de Dios | Cuando Israel era fuerte y cuando Israel era débil | Una vida sin respuestas | Elecciones de los que conocen el valor | Una convocación repentina | El mundo invisible y la verdadera fe | Hagan como la Biblia instruye | Juicio, cielo o infierno | La voz de la Madre celestial | Planes para el cielo y planes para la jubilación | La vida como el rocío sobre la hierba | Alumbren la gloria de Jerusalén al mundo entero | El significado del Día de Expiación | El Padre Ahnsahnghong es Dios, Cristo que vino por segunda vez VI | La preparación de Dios y nuestra preparación | La Pascua por la cual podemos volver a Dios
A5: ES | B5: Madre | C5: 111 | D5: La Madre Jerusalén | Búscame | Dios, la fuente de la sabiduría | La Madre Jerusalén y la vida eterna | Conozcamos a Dios | El corazón de la Madre y Sion | Nuestra Madre Celestial II | La historia de la familia de Abraham y la Madre | Discernamos entre la verdad y la falsedad | La familia celestial y la familia terrenal 2 | Los hijos de la promesa y la profecía de Abraham | La Madre Celestial Jerusalén | El corazón de los Padres celestiales | Vengan al Espíritu y la Esposa | El Espíritu y la Esposa nos llaman | Madre, gracias, la amamos | Sigan el arca del pacto | La Madre, la Fuente del Agua de la Vida | Jerusalén, el trono del juicio II | La voz de la Madre celestial | La familia celestial y la familia terrenal III | Los que pueden oír correctamente la voz de Dios | La obra de la salvación a través de la Madre | Un buen árbol lleva buenos frutos | La Madre celestial y el Lugar Santísimo
A6: ES | B6: Pascua | C6: 102 | D6: El secreto del perdón de pecados y la Pascua | La Pascua y el Orden de Melquisedec | Dios, la fuente de la sabiduría | ¡Qué hermoso será! | La educación celestial y los ojos de amor | Un desastre sin igual y la Pascua | La ciudad de refugio y la tierra | La iglesia establecida por la raíz de David y la verdad del nuevo pacto | La prueba de que somos hijos de Dios | El maná escondido y el nombre nuevo | La Pascua es la verdad que salva vidas | La Santa Comunión de la Pascua que Dios nos ordenó celebrar | La ciudad de refugio espiritual y la tierra | La verdad del árbol de la vida | La Pascua es el camino y la verdad | La comida dada por Dios | La profecía y Dios | La ley de vida, la Pascua | La invitación de Dios | La marca de Dios y la marca de la bestia | El Padre Ahnsahnghong es Dios, Cristo que vino por segunda vez VI | La Pascua que Dios nos ordenó celebrar | La Pascua por la cual podemos volver a Dios | La Pascua y la bendición de Dios | La verdad del árbol de la vida y Cristo Ahnsahnghong
